Workbook

Sheet Cover Page
C6: FINANCIAL MODELLING &
C7: VALUATION REPORT
C8: NVIDIA
F9: By Rithika Pallewar

Sheet Income Statement
B2: NVIDIA Financial Statement Model
B3: Units: USD Millions
B6: Income Statement (USD Millions)
B7: Fiscal Year | D7: FY2025 | E7: FY2024 | F7: FY2023 | G7: FY2022 | H7: FY2021 | I7: FY2020 | J7: FY2019 | K7: FY2018 | L7: FY2017 | M7: FY2016
B9: Revenue | D9: 130497 | E9: 60922 | F9: 26974 | G9: 26914 | H9: 16675 | I9: 10918 | J9: 11716 | K9: 9714 | L9: 6910 | M9: 5010
D10: =(D9-E9)/E9 -> 1.1420341 | E10: =(E9-F9)/F9 -> 1.2585453 | F10: =(F9-G9)/G9 -> 0.002229323 | G10: =(G9-H9)/H9 -> 0.61403298 | H10: =(H9-I9)/I9 -> 0.52729438 | I10: =(I9-J9)/J9 -> -0.068111984 | J10: =(J9-K9)/K9 -> 0.2060943 | K10: =(K9-L9)/L9 -> 0.40578871 | L10: =(L9-M9)/M9 -> 0.37924152 | M10: -
B12: COGS | D12: 32639 | E12: 16621 | F12: 11618 | G12: 9439 | H12: 6279 | I12: 4150 | J12: 4545 | K12: 3892 | L12: 2847 | M12: 2199
D13: =(D12-E12)/E12 -> 0.96372059 | E13: =(E12-F12)/F12 -> 0.43062489 | F13: =(F12-G12)/G12 -> 0.23085073 | G13: =(G12-H12)/H12 -> 0.50326485 | H13: =(H12-I12)/I12 -> 0.51301205 | I13: =(I12-J12)/J12 -> -0.086908691 | J13: =(J12-K12)/K12 -> 0.16778006 | K13: =(K12-L12)/L12 -> 0.36705304 | L13: =(L12-M12)/M12 -> 0.2946794 | M13: -
B15: Gross Profit | D15: =D9-D12 -> 97858 | E15: =E9-E12 -> 44301 | F15: =F9-F12 -> 15356 | G15: =G9-G12 -> 17475 | H15: =H9-H12 -> 10396 | I15: =I9-I12 -> 6768 | J15: =J9-J12 -> 7171 | K15: =K9-K12 -> 5822 | ... M15: =M9-M12 -> 2811
B16: Gross Margin % | D16: =D15/D9 -> 0.74988697 | E16: =E15/E9 -> 0.72717573 | F16: =F15/F9 -> 0.56928894 | G16: =G15/G9 -> 0.64929033 | H16: =H15/H9 -> 0.62344828 | I16: =I15/I9 -> 0.61989375 | J16: =J15/J9 -> 0.61206897 | K16: =K15/K9 -> 0.59934116 | L16: =L15/L9 -> 0.58798842 | M16: -
B18: R&D Expense | D18: 12914 | E18: 8675 | F18: 7339 | G18: 5268 | H18: 3924 | I18: 2829 | J18: 2376 | K18: 1797 | L18: 1463 | M18: 1331
D19: =(D18-E18)/E18 -> 0.48864553 | E19: =(E18-F18)/F18 -> 0.18204115 | F19: =(F18-G18)/G18 -> 0.39312832 | G19: =(G18-H18)/H18 -> 0.34250765 | H19: =(H18-I18)/I18 -> 0.38706257 | I19: =(I18-J18)/J18 -> 0.19065657 | J19: =(J18-K18)/K18 -> 0.32220367 | K19: =(K18-L18)/L18 -> 0.22829802 | L19: =(L18-M18)/M18 -> 0.099173554 | M19: -
B21: SG&A Expense | D21: 3491 | E21: 2654 | F21: 2440 | G21: 2166 | H21: 1940 | I21: 1093 | J21: 991 | K21: 815 | L21: 663 | M21: 602
D22: =(D21-E21)/E21 -> 0.31537302 | E22: =(E21-F21)/F21 -> 0.087704918 | F22: =(F21-G21)/G21 -> 0.12650046 | G22: =(G21-H21)/H21 -> 0.11649485 | H22: =(H21-I21)/I21 -> 0.77493138 | I22: =(I21-J21)/J21 -> 0.10292634 | J22: =(J21-K21)/K21 -> 0.21595092 | K22: =(K21-L21)/L21 -> 0.22926094 | L22: =(L21-M21)/M21 -> 0.1013289 | M22: -
B24: Total Operating Expenses | D24: =D18+D21 -> 16405 | E24: =E18+E21 -> 11329 | F24: =F18+F21 -> 9779 | G24: =G18+G21 -> 7434 | H24: =H18+H21 -> 5864 | I24: =I18+I21 -> 3922 | J24: =J18+J21 -> 3367 | K24: =K18+K21 -> 2612 | ... M24: =M18+M21 -> 1933
D25: =(D24-E24)/E24 -> 0.44805367 | E25: =(E24-F24)/F24 -> 0.15850291 | F25: =(F24-G24)/G24 -> 0.31544256 | G25: =(G24-H24)/H24 -> 0.26773533 | H25: =(H24-I24)/I24 -> 0.49515553 | I25: =(I24-J24)/J24 -> 0.16483516 | J25: =(J24-K24)/K24 -> 0.28905054 | K25: =(K24-L24)/L24 -> 0.22859831 | L25: =(L24-M24)/M24 -> 0.099844801 | M25: -
B27: Operating Income (EBIT) | D27: =D15-D24 -> 81453 | E27: =E15-E24 -> 32972 | F27: =F15-F24 -> 5577 | G27: =G15-G24 -> 10041 | H27: =H15-H24 -> 4532 | I27: =I15-I24 -> 2846 | J27: =J15-J24 -> 3804 | K27: =K15-K24 -> 3210 | ... M27: =M15-M24 -> 878
B28: Operating Margin % | D28: =D27/D9 -> 0.62417527 | E28: =E27/E9 -> 0.54121664 | F28: =F27/F9 -> 0.20675465 | G28: =G27/G9 -> 0.37307721 | H28: =H27/H9 -> 0.27178411 | I28: =I27/I9 -> 0.26067045 | J28: =J27/J9 -> 0.32468419 | K28: =K27/K9 -> 0.3304509 | L28: =L27/L9 -> 0.28031838 | M28: -
B30: Interest Expense | D30: -2573 | E30: -846 | F30: -43 | G30: -100 | H30: -123 | I30: -124 | J30: -92 | K30: -14 | L30: -29 | M30: -4
B33: Pre-Tax Income | D33: 84026 | E33: 33818 | F33: 4181 | G33: 9941 | H33: 4409 | I33: 2970 | J33: 3896 | K33: 3196 | L33: 1905 | M33: 743
D34: =(D33-E33)/E33 -> 1.4846531 | E34: =(E33-F33)/F33 -> 7.0884956 | F34: =(F33-G33)/G33 -> -0.57941857 | G34: =(G33-H33)/H33 -> 1.2547063 | H34: =(H33-I33)/I33 -> 0.48451178 | I34: =(I33-J33)/J33 -> -0.23767967 | J34: =(J33-K33)/K33 -> 0.21902378 | K34: =(K33-L33)/L33 -> 0.67769029 | L34: =(L33-M33)/M33 -> 1.56393 | M34: -
B36: Income Taxes | D36: 11146 | E36: 4058 | F36: -187 | G36: 189 | H36: 77 | I36: 174 | J36: -245 | K36: 149 | L36: 239 | M36: 129
B39: Income After Taxes | D39: =D33-D36 -> 72880 | E39: =E33-E36 -> 29760 | F39: =F33-F36 -> 4368 | G39: =G33-G36 -> 9752 | H39: =H33-H36 -> 4332 | I39: =I33-I36 -> 2796 | J39: =J33-J36 -> 4141 | K39: =K33-K36 -> 3047 | ... M39: =M33-M36 -> 614
D40: =(D39-E39)/E39 -> 1.4489247 | E40: =(E39-F39)/F39 -> 5.8131868 | F40: =(F39-G39)/G39 -> -0.55209188 | G40: =(G39-H39)/H39 -> 1.2511542 | H40: =(H39-I39)/I39 -> 0.54935622 | I40: =(I39-J39)/J39 -> -0.32480077 | J40: =(J39-K39)/K39 -> 0.35904168 | K40: =(K39-L39)/L39 -> 0.82893157 | L40: =(L39-M39)/M39 -> 1.713355 | M40: -
B42: Net Income | D42: 72880 | E42: 29760 | F42: 4368 | G42: 9752 | H42: 4332 | I42: 2796 | J42: 4141 | K42: 3047 | L42: 1666 | M42: 614
D43: =(D42-E42)/E42 -> 1.4489247 | E43: =(E42-F42)/F42 -> 5.8131868 | F43: =(F42-G42)/G42 -> -0.55209188 | G43: =(G42-H42)/H42 -> 1.2511542 | H43: =(H42-I42)/I42 -> 0.54935622 | I43: =(I42-J42)/J42 -> -0.32480077 | J43: =(J42-K42)/K42 -> 0.35904168 | K43: =(K42-L42)/L42 -> 0.82893157 | L43: =(L42-M42)/M42 -> 1.713355 | M43: -
B45: EBITDA | D45: =D27+'Cash Flow'!D10 -> 83317 | E45: =E27+'Cash Flow'!E10 -> 34480 | F45: 5768 | G45: 11215 | H45: 5630 | I45: 3227 | J45: 4066 | K45: 3409 | L45: 2121 | M45: 973
D46: =(D45-E45)/E45 -> 1.4163863 | E46: =(E45-F45)/F45 -> 4.9778086 | F46: =(F45-G45)/G45 -> -0.48568881 | G46: =(G45-H45)/H45 -> 0.9920071 | H46: =(H45-I45)/I45 -> 0.74465448 | I46: =(I45-J45)/J45 -> -0.2063453 | J46: =(J45-K45)/K45 -> 0.19272514 | K46: =(K45-L45)/L45 -> 0.60726073 | L46: =(L45-M45)/M45 -> 1.1798561 | M46: -
B48: Basic Shares Outstanding | D48: 24555 | E48: 24690 | F48: 24870 | G48: 24960 | H48: 24670 | I48: 24390 | J48: 24320 | K48: 23960 | L48: 21640 | M48: 21720
D49: =(D48-E48)/E48 -> -0.0054678007 | E49: =(E48-F48)/F48 -> -0.0072376357 | F49: =(F48-G48)/G48 -> -0.0036057692 | G49: =(G48-H48)/H48 -> 0.011755168 | H49: =(H48-I48)/I48 -> 0.011480115 | I49: =(I48-J48)/J48 -> 0.0028782895 | J49: =(J48-K48)/K48 -> 0.015025042 | K49: =(K48-L48)/L48 -> 0.10720887 | L49: =(L48-M48)/M48 -> -0.0036832413 | M49: -
B51: Shares Outstanding | D51: 24804 | E51: 24940 | F51: 25070 | G51: 25350 | H51: 25100 | I51: 24720 | J51: 25000 | K51: 25280 | L51: 25960 | M51: 22760
B54: Basic EPS | D54: 2.97 | E54: 1.21 | F54: 0.18 | G54: 0.391 | H54: 0.176 | I54: 0.115 | J54: 0.1703 | K54: 0.1273 | L54: 0.077 | M54: 0.0283
B57: EPS - Earnings Per Share | D57: 2.94 | E57: 1.19 | F57: 0.17 | G57: 0.385 | H57: 0.173 | I57: 0.113 | J57: 0.1658 | K57: 0.1205 | L57: 0.0643 | M57: 0.027

Sheet Balance Sheet
B6: Balance Sheet (USD Millions)
B7: Fiscal Year | D7: FY2025 | E7: FY2024 | F7: FY2023 | G7: FY2022 | H7: FY2021 | I7: FY2020 | J7: FY2019 | K7: FY2018 | L7: FY2017 | M7: FY2016
B9: Cash On Hand | D9: 43210 | E9: 25984 | F9: 13296 | G9: 21208 | H9: 11561 | I9: 10897 | J9: 7422 | K9: 7108 | L9: 6798 | M9: 5037
B10: Receivables | D10: 23065 | E10: 9999 | F10: 3827 | G10: 4650 | H10: 2429 | I10: 1657 | J10: 1424 | K10: 1265 | L10: 826 | M10: 505
B11: Inventory | D11: 10080 | E11: 5282 | F11: 5159 | G11: 2605 | H11: 1826 | I11: 979 | J11: 1575 | K11: 796 | L11: 794 | M11: 418
B12: Pre-Paid Expenses | D12: 3771 | E12: 3080 | F12: 791 | G12: 366 | H12: 239 | I12: 157 | J12: 136 | K12: 86 | L12: 118 | M12: 93
B13: Other Current Assets | D13: - | E13: - | F13: - | G13: - | H13: - | I13: - | J13: - | K13: - | L13: - | M13: -
A14: Total Current Assets | D14: =SUM(D9:D12) -> 80126 | E14: =SUM(E9:E12) -> 44345 | F14: =SUM(F9:F12) -> 23073 | G14: =SUM(G9:G12) -> 28829 | H14: =SUM(H9:H12) -> 16055 | I14: =SUM(I9:I12) -> 13690 | J14: =SUM(J9:J12) -> 10557 | K14: =SUM(K9:K12) -> 9255 | ... M14: =SUM(M9:M12) -> 6053
B15: Property, Plant, And Equipment | D15: 6283 | E15: 3914 | F15: 3807 | G15: 2778 | H15: 2149 | I15: 1674 | J15: 1404 | K15: 997 | L15: 521 | M15: 466
B16: Long-Term Investments
B17: Goodwill And Intangible Assets | D17: 5995 | E17: 5542 | F17: 6048 | G17: 6688 | H17: 6930 | I17: 667 | J17: 663 | K17: 670 | L17: 722 | M17: 784
B18: Other Long-Term Assets | D18: 6425 | E18: 4500 | F18: 3820 | G18: 3841 | H18: 2144 | I18: 118 | J18: 108 | K18: 319 | L18: 62 | M18: 67
A19: Total Long-Term Assets | D19: 31475 | E19: 21383 | F19: 18109 | G19: 15358 | H19: 12736 | I19: 3625 | J19: 2735 | K19: 1986 | L19: 1305 | M19: 1317
A20: Total Assets | D20: 111601 | E20: 65728 | F20: 41182 | G20: 44187 | H20: 28791 | I20: 17315 | J20: 13292 | K20: 11241 | L20: 9841 | M20: 7370
A22: Total Current Liabilities | D22: 18047 | E22: 10631 | F22: 6563 | G22: 4335 | H22: 3925 | I22: 1784 | J22: 1329 | K22: 1153 | L22: 1788 | M22: 2351
B23: Long Term Debt | D23: 8463 | E23: 8459 | F23: 9703 | G23: 10946 | H23: 5964 | I23: 1991 | J23: 1988 | K23: 1985 | L23: 2014 | M23: 97
B24: Other Non-Current Liabilities | D24: 4245 | E24: 2541 | F24: 1913 | G24: 1553 | H24: 1375 | I24: 775 | J24: 633 | K24: 632 | L24: 277 | M24: 453
A25: Total Long Term Liabilities | D25: 14227 | E25: 12119 | F25: 12518 | G25: 13240 | H25: 7973 | I25: 3327 | J25: 2621 | K25: 2617 | L25: 2291 | M25: 550
A26: Total Liabilities | D26: =D22+D25 -> 32274 | E26: =E22+E25 -> 22750 | F26: =F22+F25 -> 19081 | G26: =G22+G25 -> 17575 | H26: =H22+H25 -> 11898 | I26: =I22+I25 -> 5111 | J26: =J22+J25 -> 3950 | K26: =K22+K25 -> 3770 | ... M26: =M22+M25 -> 2901
B28: Common Stock Net | D28: 24 | E28: 25 | F28: 2 | G28: 3 | H28: 3 | I28: 1 | J28: 1 | K28: 1 | L28: 1 | M28: 1
B29: Retained Earnings | D29: 68038 | E29: 29817 | F29: 10171 | G29: 16235 | H29: 18908 | I29: 14971 | J29: 12565 | K29: 8787 | L29: 6108 | M29: 4350
B30: Comprehensive Income | D30: 28 | E30: 27 | F30: -43 | G30: -11 | H30: 19 | I30: 1 | J30: -12 | K30: -18 | L30: -16 | M30: -4
B31: Other Share Holders Equity | D31: - | E31: - | F31: - | G31: - | H31: - | I31: - | J31: - | K31: - | L31: - | M31: -
A32: Share Holder Equity | D32: 79327 | E32: 42978 | F32: 22101 | G32: 26612 | H32: 16893 | I32: 12204 | J32: 9342 | K32: 7471 | L32: 5762 | M32: 4469
A33: Total Liabilities And Share Holders Equity | D33: =D26+D32 -> 111601 | E33: =E26+E32 -> 65728 | F33: =F26+F32 -> 41182 | G33: =G26+G32 -> 44187 | H33: =H26+H32 -> 28791 | I33: =I26+I32 -> 17315 | J33: =J26+J32 -> 13292 | K33: =K26+K32 -> 11241 | ... M33: =M26+M32 -> 7370

Sheet Cash Flow
B6: Cash Flow Statement (USD Millions)
B7: Fiscal Year | D7: FY2025 | E7: FY2024 | F7: FY2023 | G7: FY2022 | H7: FY2021 | I7: FY2020 | J7: FY2019 | K7: FY2018 | L7: FY2017 | M7: FY2016
A9: Net Income/Loss | D9: ='Income Statement'!D42 -> 72880 | E9: ='Income Statement'!E42 -> 29760 | F9: ='Income Statement'!F42 -> 4368 | G9: ='Income Statement'!G42 -> 9752 | H9: ='Income Statement'!H42 -> 4332 | I9: ='Income Statement'!I42 -> 2796 | J9: ='Income Statement'!J42 -> 4141 | K9: ='Income Statement'!K42 -> 3047 | ... M9: ='Income Statement'!M42 -> 614
B10: Total Depreciation And Amortization | D10: 1864 | E10: 1508 | F10: 1544 | G10: 1174 | H10: 1098 | I10: 381 | J10: 262 | K10: 199 | L10: 187 | M10: 226
B11: Other Non-Cash Items | D11: -1272 | E11: 544 | F11: 1936 | G11: 1545 | H11: 1095 | I11: 867 | J11: 197 | K11: 71 | L11: 498 | M11: 386
B12: Total Non-Cash Items | D12: =D10+D11 -> 592 | E12: =E10+E11 -> 2052 | F12: =F10+F11 -> 3480 | G12: =G10+G11 -> 2719 | H12: =H10+H11 -> 2193 | I12: =I10+I11 -> 1248 | J12: =J10+J11 -> 459 | K12: =K10+K11 -> 270 | ... M12: =M10+M11 -> 612
B13: Change In Accounts Receivable | D13: -13063 | E13: -6172 | F13: 822 | G13: -2215 | H13: -550 | I13: -233 | J13: -149 | K13: -440 | L13: -321 | M13: -32
B14: Change In Inventories | D14: -4781 | E14: -98 | F14: -2554 | G14: -774 | H14: -524 | I14: 597 | J14: -776 | K14: 0 | L14: -375 | M14: 66
B15: Change In Accounts Payable | D15: 3357 | E15: 1531 | F15: -551 | G15: 568 | H15: 312 | I15: 194 | J15: -135 | K15: 90 | L15: 184 | M15: -11
B16: Change In Assets/Liabilities | D16: 826 | E16: -1008 | F16: -1265 | G16: -1523 | H16: -231 | I16: 105 | J16: -53 | K16: 21 | L16: -18 | M16: -16
B17: Total Change In Assets/Liabilities | D17: -9383 | E17: -3722 | F17: -2207 | G17: -3363 | H17: -703 | I17: 717 | J17: -857 | K17: 185 | L17: -679 | M17: -51
A19: Cash Flow From Operating Activities | D19: =D9+D12+D17 -> 64089 | E19: =E9+E12+E17 -> 28090 | F19: =F9+F12+F17 -> 5641 | G19: =G9+G12+G17 -> 9108 | H19: =H9+H12+H17 -> 5822 | I19: =I9+I12+I17 -> 4761 | J19: =J9+J12+J17 -> 3743 | K19: =K9+K12+K17 -> 3502 | ... M19: =M9+M12+M17 -> 1175
B20: Net Change In Property, Plant, And Equipment | D20: -3236 | E20: -1069 | F20: -1833 | G20: -976 | H20: -1128 | I20: -489 | J20: -600 | K20: -591 | L20: -169 | M20: -79
B21: Net Change In Intangible Assets
B22: Net Acquisitions/Divestitures | D22: -1007 | E22: -83 | F22: -49 | G22: -263 | H22: -8524 | I22: -4 | J22: 0 | K22: 0 | L22: 0 | M22: 0
B23: Net Change In Short-term Investments | D23: -14885 | E23: -8429 | F23: 9334 | G23: -8591 | H23: -9989 | I23: 6648 | J23: -3488 | K23: 1869 | L23: -624 | M23: -345
B24: Net Change In Long-Term Investments | D24: -1315 | E24: -861 | F24: -77
B25: Net Change In Investments - Total | D25: -16200 | E25: -9290 | F25: 9257 | G25: -8591 | H25: -9989 | I25: 6648 | J25: -3488 | K25: 1869 | L25: -624 | M25: -345
B26: Investing Activities - Other | D26: 22 | E26: -124 | F26: 0 | G26: 0 | H26: -34 | I26: -10 | J26: -9 | K26: 0 | L26: 0 | M26: 24
A28: Cash Flow From Investing Activities | D28: =D20+D22+D25+D26 -> -20421 | E28: =E20+E22+E25+E26 -> -10566 | F28: =F20+F22+F25+F26 -> 7375 | G28: =G20+G22+G25+G26 -> -9830 | H28: =H20+H22+H25+H26 -> -19675 | I28: =I20+I22+I25+I26 -> 6145 | J28: =J20+J22+J25+J26 -> -4097 | K28: =K20+K22+K25+K26 -> 1278 | ... M28: =M20+M22+M25+M26 -> -400
B29: Net Long-Term Debt | D29: -1250 | E29: -1250 | F29: 0 | G29: 3977 | H29: 4968 | I29: 0 | J29: 0 | K29: 0 | L29: 1988 | M29: 0
B30: Net Current Debt | J30: -16 | K30: -812 | L30: -673 | M30: 0
B31: Debt Issuance/Retirement Net - Total | D31: -1250 | E31: -1250 | F31: 0 | G31: 3977 | H31: 4968 | I31: 0 | J31: -16 | K31: -812 | L31: 1315 | M31: 0
B32: Net Common Equity Issued/Repurchased | D32: -33216 | E32: -9130 | F32: -9684 | G32: 281 | H32: 0 | I32: 0 | J32: -1579 | K32: -909 | L32: -739 | M32: -587
B33: Net Total Equity Issued/Repurchased | D33: -33216 | E33: -9130 | F33: -9684 | G33: 281 | H33: 0 | I33: 0 | J33: -1579 | K33: -909 | L33: -739 | M33: -587
B34: Total Common And Preferred Stock Dividends Paid | D34: -834 | E34: -395 | F34: -398 | G34: -399 | H34: -395 | I34: -390 | J34: -371 | K34: -341 | L34: -261 | M34: -213
B35: Financial Activities - Other | D35: -7059 | E35: -2858 | F35: -1535 | G35: -1994 | H35: -769 | I35: -402 | J35: -900 | K35: -482 | L35: -24 | M35: 124
A37: Cash Flow From Financial Activities | D37: -42359 | E37: -13633 | F37: -11617 | G37: 1865 | H37: 3804 | I37: -792 | J37: -2866 | K37: -2544 | L37: 291 | M37: -676
B38: Net Cash Flow | D38: =D19+D28+D37 -> 1309 | E38: =E19+E28+E37 -> 3891 | F38: =F19+F28+F37 -> 1399 | G38: =G19+G28+G37 -> 1143 | H38: =H19+H28+H37 -> -10049 | I38: =I19+I28+I37 -> 10114 | J38: =J19+J28+J37 -> -3220 | K38: =K19+K28+K37 -> 2236 | ... M38: =M19+M28+M37 -> 99
B39: Stock-Based Compensation | D39: 4737 | E39: 3549 | F39: 2709 | G39: 2004 | H39: 1397 | I39: 844 | J39: 557 | K39: 391 | L39: 247 | M39: 204
B40: Common Stock Dividends Paid | D40: -834 | E40: -395 | F40: -398 | G40: -399 | H40: -395 | I40: -390 | J40: -371 | K40: -341 | L40: -261 | M40: -213

Sheet ROIC
B6: Calculation OF ROIC
B7: Fiscal Year | D7: FY2025 | E7: FY2024 | F7: FY2023 | G7: FY2022 | H7: FY2021
B9: Receivables | D9: ='Balance Sheet'!D10 -> 23065 | E9: ='Balance Sheet'!E10 -> 9999 | F9: ='Balance Sheet'!F10 -> 3827 | G9: ='Balance Sheet'!G10 -> 4650 | H9: ='Balance Sheet'!H10 -> 2429
B10: Inventory | D10: ='Balance Sheet'!D11 -> 10080 | E10: ='Balance Sheet'!E11 -> 5282 | F10: ='Balance Sheet'!F11 -> 5159 | G10: ='Balance Sheet'!G11 -> 2605 | H10: ='Balance Sheet'!H11 -> 1826
B11: Pre-Paid Expenses | D11: ='Balance Sheet'!D12 -> 3771 | E11: ='Balance Sheet'!E12 -> 3080 | F11: ='Balance Sheet'!F12 -> 791 | G11: ='Balance Sheet'!G12 -> 366 | H11: ='Balance Sheet'!H12 -> 239
B12: Operating Current Assets | D12: =SUM(D9:D11) -> 36916 | E12: =SUM(E9:E11) -> 18361 | F12: =SUM(F9:F11) -> 9777 | G12: =SUM(G9:G11) -> 7621 | H12: =SUM(H9:H11) -> 4494
B14: Total Current Liabilities | D14: ='Balance Sheet'!D22 -> 18047 | E14: ='Balance Sheet'!E22 -> 10631 | F14: ='Balance Sheet'!F22 -> 6563 | G14: ='Balance Sheet'!G22 -> 4335 | H14: ='Balance Sheet'!H22 -> 3925
B16: Net Working Capital | D16: =D12-D14 -> 18869 | E16: =E12-E14 -> 7730 | F16: =F12-F14 -> 3214 | G16: =G12-G14 -> 3286 | H16: =H12-H14 -> 569
B18: Non Current Assets | D18: - | E18: - | F18: - | G18: - | H18: -
B19: Net Property, Plant, And Equipment | D19: ='Balance Sheet'!D15 -> 6283 | E19: ='Balance Sheet'!E15 -> 3914 | F19: ='Balance Sheet'!F15 -> 3807 | G19: ='Balance Sheet'!G15 -> 2778 | H19: ='Balance Sheet'!H15 -> 2149
B20: Goodwill And Intangible Assets | D20: ='Balance Sheet'!D17 -> 5995 | E20: ='Balance Sheet'!E17 -> 5542 | F20: ='Balance Sheet'!F17 -> 6048 | G20: ='Balance Sheet'!G17 -> 6688 | H20: ='Balance Sheet'!H17 -> 6930
B22: Invested Capital | D22: =D16+D19+D20 -> 31147 | E22: =E16+E19+E20 -> 17186 | F22: =F16+F19+F20 -> 13069 | G22: =G16+G19+G20 -> 12752 | H22: =H16+H19+H20 -> 9648
B24: Oprating Income (EBIT) | D24: ='Income Statement'!D27 -> 81453 | E24: ='Income Statement'!E27 -> 32972 | F24: ='Income Statement'!F27 -> 5577 | G24: ='Income Statement'!G27 -> 10041 | H24: ='Income Statement'!H27 -> 4532
B25: Tax Rate | D25: ='Income Statement'!D36/'Income Statement'!D33 -> 0.13264942 | E25: ='Income Statement'!E36/'Income Statement'!E33 -> 0.11999527 | F25: ='Income Statement'!F36/'Income Statement'!F33 -> -0.044726142 | G25: ='Income Statement'!G36/'Income Statement'!G33 -> 0.019012172 | H25: ='Income Statement'!H36/'Income Statement'!H33 -> 0.017464278
B26: NOPAT | D26: =D24*(1-D25) -> 70648.307 | E26: =E24*(1-E25) -> 29015.516 | F26: =F24*(1-F25) -> 5826.4377 | G26: =G24*(1-G25) -> 9850.0988 | H26: =H24*(1-H25) -> 4452.8519
B28: ROIC | D28: =D26/D22 -> 2.2682219 | E28: =E26/E22 -> 1.6883228 | F28: =F26/F22 -> 0.44582123 | G28: =G26/G22 -> 0.7724356 | H28: =H26/H22 -> 0.46153108

Sheet WACC
B7: Cost of Equity (CAPM) | G7: Cost of Debt
B8: Risk Free Rate | E8: 0.042 | G8: Interest Expense | J8: 2573
B9: Beta | E9: 1.7 | G9: Total Debt | J9: ='Balance Sheet'!D23 -> 8463
B10: Market Risk Premium | E10: 0.058 | G10: Implied Cost of Debt | J10: =J8/J9 -> 0.3040293
G11: Assumed Cost of Debt | J11: 0.04
G12: Tax Rate | J12: =ROIC!D25 -> 0.13264942
B13: Cost of Equity | E13: =E8+(E9*E10) -> 0.1406 | G13: After-Tax Cost of Debt | J13: =J11*(1-J12) -> 0.034694023
B15: Capital Structure
B16: Share Price | E16: 110
B17: Shares Outstanding | E17: 24804
B18: Market Value of Equity (E) | E18: 2728440
B19: Total Debt | E19: 8463
B20: Total Capital (V) | E20: 2736903
B21: Equity Weight (E/V) | E21: =E18/E20 -> 0.99690782
B22: Debt Weight (D/V) | E22: =E19/E20 -> 0.0030921812
B24: WACC (Weighted Average Cost of Capital)
B25: Cost of Equity | E25: 0.1406
B26: Equity Weight | E26: 0.9969
B27: Cost of Debt (After Tax) | E27: 0.0347
B28: Debt Weight | E28: 0.0031
B29: WACC | E29: =(E26*E25)+(E28*E27) -> 0.14027171

Sheet UFCF
B6: Calculation Unlevered Free Cash Flow (UFCF).
D7: FY2025 | E7: FY2026 | F7: FY2027 | G7: FY2028 | H7: FY2029
B8: EBIT | D8: =ROIC!D24 -> 81453 | E8: =ROIC!E24 -> 32972 | F8: =ROIC!F24 -> 5577 | G8: =ROIC!G24 -> 10041 | H8: =ROIC!H24 -> 4532
B9: Tax Rate | D9: =ROIC!D25 -> 0.13264942 | E9: =ROIC!E25 -> 0.11999527 | F9: =ROIC!F25 -> -0.044726142 | G9: =ROIC!G25 -> 0.019012172 | H9: =ROIC!H25 -> 0.017464278
B10: NOPAT | D10: =ROIC!D26 -> 70648.307 | E10: =ROIC!E26 -> 29015.516 | F10: =ROIC!F26 -> 5826.4377 | G10: =ROIC!G26 -> 9850.0988 | H10: =ROIC!H26 -> 4452.8519
B11: Depreciation & Amortization | D11: ='Cash Flow'!D10 -> 1864 | E11: ='Cash Flow'!E10 -> 1508 | F11: ='Cash Flow'!F10 -> 1544 | G11: ='Cash Flow'!G10 -> 1174 | H11: ='Cash Flow'!H10 -> 1098
B12: Capital Ependiture | D12: =3236 -> 3236 | E12: =3236 -> 3236 | F12: =3236 -> 3236 | G12: =3236 -> 3236 | H12: =3236 -> 3236
B13: Change in Net Working Capital | D13: =ROIC!D16-ROIC!E16 -> 11139 | E13: =ROIC!E16-ROIC!F16 -> 4516 | F13: =ROIC!F16-ROIC!G16 -> -72 | G13: =ROIC!G16-ROIC!H16 -> 2717 | H13: =ROIC!H16-ROIC!I16 -> 569
B14: Unlevered Free Cash Flow | D14: =D10+D11-D12-D13 -> 58137.307 | E14: =E10+E11-E12-E13 -> 22771.516 | F14: =F10+F11-F12-F13 -> 4206.4377 | G14: =G10+G11-G12-G13 -> 5071.0988 | H14: =H10+H11-H12-H13 -> 1745.8519

Sheet TERMINAL VALUE
B7: Calculation Of PV of FCF
E8: 2025A | H8: 2026E | I8: 2027E | J8: 2028E | K8: 2029E
B9: Revenue | E9: ='Income Statement'!D9 -> 130497 | H9: =E9*(1+H10) -> 169646.1 | I9: =H9*(1+I10) -> 212057.62 | J9: =I9*(1+J10) -> 254469.15 | K9: =J9*(1+K10) -> 292639.52
B10: Revenue Growth | E10: ='Income Statement'!D10 -> 1.1420341 | H10: 0.3 | I10: 0.25 | J10: 0.2 | K10: 0.15
B11: EBIT | E11: ='Income Statement'!D27 -> 81453 | H11: =H9*H12 -> 101787.66 | I11: =I9*I12 -> 122993.42 | J11: =J9*J12 -> 142502.72 | K11: =K9*K12 -> 160951.74
B12: EBIT Margin | E12: ='Income Statement'!D28 -> 0.62417527 | H12: 0.6 | I12: 0.58 | J12: 0.56 | K12: 0.55
B13: Tax Rate | E13: 0.13264942 | H13: 0.21 | I13: 0.21 | J13: 0.21 | K13: 0.21
B14: NOPAT | E14: 70648.307 | H14: =H11*(1-H13) -> 80412.251 | I14: =I11*(1-I13) -> 97164.804 | J14: =J11*(1-J13) -> 112577.15 | K14: =K11*(1-K13) -> 127151.87
B15: D&A | E15: 1864 | H15: =H9*E16 -> 2423.2 | I15: =I9*H16 -> 3029 | J15: =J9*I16 -> 3634.8 | K15: =K9*J16 -> 4180.02
B16: Corporate Tax | E16: =E15/E9 -> 0.014283853 | H16: =H15/H9 -> 0.014283853 | I16: =I15/I9 -> 0.014283853 | J16: =J15/J9 -> 0.014283853 | K16: =K15/K9 -> 0.014283853
B17: CapEx % of revenue | E17: =E18/E9 -> 0.024797505
B18: CapEx | E18: =3236 -> 3236 | H18: =H9*$E$17 -> 4206.8 | I18: =I9*$E$17 -> 5258.5 | J18: =J9*$E$17 -> 6310.2 | K18: =K9*$E$17 -> 7256.73
B19: NWC % revenue | E19: =E20/E9 -> 0.14459336
B20: NWC | E20: =ROIC!D16 -> 18869 | H20: =H9*$E$19 -> 24529.7 | I20: =I9*$E$19 -> 30662.125 | J20: =J9*$E$19 -> 36794.55 | K20: =K9*$E$19 -> 42313.732
B21: ΔNWC | H21: =H20-E20 -> 5660.7 | I21: =I20-H20 -> 6132.425 | J21: =J20-I20 -> 6132.425 | K21: =K20-J20 -> 5519.1825
B22: Free Cash Flow | E22: =E14+E15-E18-E20 -> 50407.307 | H22: =H14+H15-H18-H21 -> 72967.951 | I22: =I14+I15-I18-I21 -> 88802.879 | J22: =J14+J15-J18-J21 -> 103769.33 | K22: =K14+K15-K18-K21 -> 118555.98
B23: Discounting Factor | H23: =1/(1+$E$28)^1 -> 0.87698396 | I23: =1/(1+$E$28)^2 -> 0.76910087 | J23: =1/(1+$E$28)^3 -> 0.67448912 | K23: =1/(1+$E$28)^4 -> 0.59151614
B24: PV of FCFF | H24: =H22*H23 -> 63991.723 | I24: =I22*I23 -> 68298.371 | J24: =J22*J23 -> 69991.282 | K24: =K22*K23 -> 70127.776
B26: Expected Growth
B27: Terminal Growth rate | E27: 0.025
B28: WACC | E28: =WACC!E29 -> 0.14027171
B30: Calaculation of Terminal Value | G30: Sensitivity Analysis – Implied Share Price
B31: Terminal Growth | E31: =E27 -> 0.025 | G31: WACC \ g | H31: 0.015 | I31: 0.02 | J31: 0.025 | K31: 0.03
B32: WACC | E32: =E28 -> 0.14027171 | G32: 0.12 | H32: 48 | I32: 52 | J32: 57 | K32: 63
E33: =E32-E31 -> 0.11527171 | G33: 0.13 | H33: 41 | I33: 44 | J33: 48 | K33: 52
B34: Final Year FCF (2029) | E34: =K22 -> 118555.98 | G34: 0.14 | H34: 34 | I34: 36 | J34: 38 | K34: 41
B35: FCF in Terminal Year (2030) | E35: =K22 * (1 + 2.5%) -> 121519.88 | G35: 0.15 | H35: 30 | I35: 32 | J35: 34 | K35: 36
G36: 0.16 | H36: 26 | I36: 28 | J36: 30 | K36: 32
B37: Terminal Value | E37: =E35/E33 -> 1054203.8
B38: Discount Factor | E38: =(1+14%)^4 -> 1.6889602
B40: Calculation of Equity Value Per Share
B41: PV of FCFF | E41: =SUM(H24:K24) -> 272409.15
B42: PV of Terminal Value | E42: =E37/E38 -> 624173.3
B45: Enterprise Value | E45: =E41+E42 -> 896582.46
B46: Add:Cash | E46: ='Balance Sheet'!D9 -> 43210
B47: Less:Debt | E47: ='Balance Sheet'!D23 -> 8463
B48: Equity Value | E48: =E45+E46-E47 -> 931329.46
B49: Shares Outstanding | E49: ='Income Statement'!D51 -> 24804
B50: Implied Share Price | E50: =E48/E49 -> 37.547551

Sheet Comparable Valuation
B7: Comparable Company Valuation
D8: Market Data | J8: Financials | N8: Valuation
B9: Company | D9: Share Price | E9: Shares Outstanding | F9: Equity Value | G9: Net Debt | H9: Enterprise Value | J9: Revenue | K9: EBITDA | L9: Net Income | N9: EV/Revenue | O9: EV/EBITDA | P9: P/E
B10: NVIDIA | D10: 110 | E10: 24804 | F10: =E10*D10 -> 2728440 | G10: -34747 | H10: =F10+G10 -> 2693693 | J10: 130497 | K10: 83317 | L10: 72880 | N10: =H10/J10 -> 20.6418 | O10: =H10/K10 -> 32.330653 | P10: =F10/L10 -> 37.437431
B11: AMD | D11: 180 | E11: 1620 | F11: =E11*D11 -> 291600 | G11: 1200 | H11: =F11+G11 -> 292800 | J11: 23600 | K11: 4800 | L11: 2200 | N11: =H11/J11 -> 12.40678 | O11: =H11/K11 -> 61 | P11: =F11/L11 -> 132.54545
B12: Intel | D12: 44 | E12: 4220 | F12: =E12*D12 -> 185680 | G12: 36000 | H12: =F12+G12 -> 221680 | J12: 54200 | K12: 13000 | L12: 1700 | N12: =H12/J12 -> 4.0900369 | O12: =H12/K12 -> 17.052308 | P12: =F12/L12 -> 109.22353
B13: Broadcom | D13: 1350 | E13: 470 | F13: =E13*D13 -> 634500 | G13: 38000 | H13: =F13+G13 -> 672500 | J13: 35800 | K13: 23600 | L13: 14000 | N13: =H13/J13 -> 18.784916 | O13: =H13/K13 -> 28.495763 | P13: =F13/L13 -> 45.321429
B14: Qualcomm | D14: 175 | E14: 1110 | F14: =E14*D14 -> 194250 | G14: -8000 | H14: =F14+G14 -> 186250 | J14: 36300 | K14: 13500 | L14: 9200 | N14: =H14/J14 -> 5.130854 | O14: =H14/K14 -> 13.796296 | P14: =F14/L14 -> 21.11413
B15: TSMC | D15: 140 | E15: 5180 | F15: =E15*D15 -> 725200 | G15: -22000 | H15: =F15+G15 -> 703200 | J15: 69300 | K15: 44200 | L15: 31800 | N15: =H15/J15 -> 10.147186 | O15: =H15/K15 -> 15.909502 | P15: =F15/L15 -> 22.805031
B18: Low (Min) | N18: =MIN(N10:N15) -> 4.0900369 | O18: =MIN(O10:O15) -> 13.796296 | P18: =MIN(P10:P15) -> 21.11413
B19: 25th Percentile | N19: =_xlfn.PERCENTILE.INC(N10:N15,0.25) -> 6.384937 | O19: =_xlfn.PERCENTILE.INC(O10:O15,0.25) -> 16.195204 | P19: =_xlfn.PERCENTILE.INC(P10:P15,0.25) -> 26.463131
B20: Median | N20: =MEDIAN(N10:N15) -> 11.276983 | O20: =MEDIAN(O10:O15) -> 22.774035 | P20: =MEDIAN(P10:P15) -> 41.37943
B21: Average | N21: =AVERAGE(N10:N15) -> 11.866929 | O21: =AVERAGE(O10:O15) -> 28.09742 | P21: =AVERAGE(P10:P15) -> 61.407834
B22: 75th Percentile | N22: =_xlfn.PERCENTILE.INC(N10:N15,0.75) -> 17.190382 | O22: =_xlfn.PERCENTILE.INC(O10:O15,0.75) -> 31.37193 | P22: =_xlfn.PERCENTILE.INC(P10:P15,0.75) -> 93.248004
B23: High (Max) | N23: =MAX(N10:N15) -> 20.6418 | O23: =MAX(O10:O15) -> 61 | P23: =MAX(P10:P15) -> 132.54545
B26: Nvidia Comparable Valuation | N26: EV/Revenue | O26: EV/EBITDA | P26: P/E
B27: Implied Enterprise Value | N27: =J10*N20 -> 1471612.4 | O27: =K10*O20 -> 1897464.3 | P27: —
B28: Net Debt | N28: -34747 | O28: -34747 | P28: —
B29: Implied Market Value | N29: =N27-N28 -> 1506359.4 | O29: =O27-O28 -> 1932211.3 | P29: 3002656
B30: Shares Outstanding | N30: 24804 | O30: 24804 | P30: 24804
B31: Implied Value Per Share | N31: =N29/N30 -> 60.730505 | O31: =O29/O30 -> 77.899181 | P31: =P29/P30 -> 121.05531
N32: OVERVALUED | O32: OVERVALUED | P32: SLIGHTLY UNDERVALUED
B34: Advanced Micro Devices Comparable Valuation | N34: EV/Revenue | O34: EV/EBITDA | P34: P/E
B35: Implied Enterprise Value | N35: =J11*N20 -> 266136.8 | O35: =K11*O20 -> 109315.37 | P35: —
B36: Net Debt | N36: -1200 | O36: -1200 | P36: —
B37: Implied Market Value | N37: =N35-N36 -> 267336.8 | O37: =O35-O36 -> 110515.37 | P37: 90640
B38: Shares Outstanding | N38: 1620 | O38: 1620 | P38: 1620
B39: Implied Value Per Share | N39: =N37/N38 -> 165.02271 | O39: =O37/O38 -> 68.219364 | P39: =P37/P38 -> 55.950617
B42: Intel Comparable Valuation | N42: EV/Revenue | O42: EV/EBITDA | P42: P/E
B43: Implied Enterprise Value | N43: =J12*N20 -> 611212.47 | O43: =K12*O20 -> 296062.46 | P43: —
B44: Net Debt | N44: -36000 | O44: -36000 | P44: —
B45: Implied Market Value | N45: =N43-N44 -> 647212.47 | O45: =O43-O44 -> 332062.46 | P45: 70040
B46: Shares Outstanding | N46: 4220 | O46: 4220 | P46: 4220
B47: Implied Value Per Share | N47: =N45/N46 -> 153.36788 | O47: =O45/O46 -> 78.687786 | P47: =P45/P46 -> 16.597156
B50: Broadcom Comparable Valuation | N50: EV/Revenue | O50: EV/EBITDA | P50: P/E
B51: Implied Enterprise Value | N51: =J13*N20 -> 403715.99 | O51: =K13*O20 -> 537467.23 | P51: —
B52: Net Debt | N52: -38000 | O52: -38000 | P52: —
B53: Implied Market Value | N53: =N51-N52 -> 441715.99 | O53: =O51-O52 -> 575467.23 | P53: 576800
B54: Shares Outstanding | N54: 470 | O54: 470 | P54: 470
B55: Implied Value Per Share | N55: =N53/N54 -> 939.82125 | O55: =O53/O54 -> 1224.3984 | P55: =P53/P54 -> 1227.234
...

Sheet DUPONT
B6: DUPONT ANALYSIS
B7: Return on Equity
D8: FY2021 | E8: FY2022 | F8: FY2023 | G8: FY2024 | H8: FY2025
B9: Net Profit | D9: 4332 | E9: 9752 | F9: 4368 | G9: 29760 | H9: 72880
B10: Average Shareholder’s Equity | D10: 16893 | E10: 26612 | F10: 22101 | G10: 42978 | H10: 79327
B11: Return on Equity | D11: =D9/D10 -> 0.25643758 | E11: =E9/E10 -> 0.36645123 | F11: =F9/F10 -> 0.19763812 | G11: =G9/G10 -> 0.6924473 | H11: =H9/H10 -> 0.91872881
B13: Return on Equity – DuPont Equation
B15: Net Profit | D15: 4332 | E15: 9752 | F15: 4368 | G15: 29760 | H15: 72880
B16: Revenue | D16: 16675 | E16: 26914 | F16: 26974 | G16: 60922 | H16: 130497
B17: Net Profit Margin (A) | D17: 0.26 | E17: 0.362 | F17: 0.162 | G17: 0.488 | H17: 0.559
B19: Revenue | D19: 16675 | E19: 26914 | F19: 26974 | G19: 60922 | H19: 130497
B20: Average Total Assets | D20: 28791 | E20: 44187 | F20: 41182 | G20: 65728 | H20: 111601
B21: Assets Turnover Ratio (B) | D21: 0.58 | E21: 0.61 | F21: 0.65 | G21: 0.93 | H21: 1.17
B23: Average Total Assets | D23: 28791 | E23: 44187 | F23: 41182 | G23: 65728 | H23: 111601
B24: Average Shareholder’s Equity | D24: 16893 | E24: 26612 | F24: 22101 | G24: 42978 | H24: 79327
B25: Equity Multiplier (C) | D25: 1.7 | E25: 1.66 | F25: 1.86 | G25: 1.53 | H25: 1.41
B27: Return on Equity (A×B×C) | D27: =D17*D21*D25 -> 0.25636 | E27: =E17*E21*E25 -> 0.3665612 | F27: =F17*F21*F25 -> 0.195858 | G27: =G17*G21*G25 -> 0.6943752 | H27: =H17*H21*H25 -> 0.9221823
B29: Return on Assets
D30: FY2021 | E30: FY2022 | F30: FY2023 | G30: FY2024 | H30: FY2025
B31: Net Profit | D31: 4332 | E31: 9752 | F31: 4368 | G31: 29760 | H31: 72880
B32: Average Total Assets | D32: 28791 | E32: 44187 | F32: 41182 | G32: 65728 | H32: 111601
B33: Return on Assets | D33: =D31/D32 -> 0.15046369 | E33: =E31/E32 -> 0.2206984 | F33: =F31/F32 -> 0.10606576 | G33: =G31/G32 -> 0.45277507 | H33: =H31/H32 -> 0.65304074
B35: Return on Assets – DuPont Equation
B37: Net Profit | D37: 4332 | E37: 9752 | F37: 4368 | G37: 29760 | H37: 72880
B38: Revenue | D38: 16675 | E38: 26914 | F38: 26974 | G38: 60922 | H38: 130497
B39: Net Profit Margin (A) | D39: =D37/D38 -> 0.2597901 | E39: =E37/E38 -> 0.3623393 | F39: =F37/F38 -> 0.16193371 | G39: =G37/G38 -> 0.48849348 | H39: =H37/H38 -> 0.55848027
B41: Revenue | D41: 16675 | E41: 26914 | F41: 26974 | G41: 60922 | H41: 130497
B42: Average Total Assets | D42: 28791 | E42: 44187 | F42: 41182 | G42: 65728 | H42: 111601
B43: Assets Turnover Ratio (B) | D43: =D41/D42 -> 0.57917405 | E43: =E41/E42 -> 0.60909317 | F43: =F41/F42 -> 0.6549949 | G43: =G41/G42 -> 0.92688048 | H43: =H41/H42 -> 1.1693175
B45: Return on Assets (A×B) | D45: =D39*D43 -> 0.15046369 | E45: =E39*E43 -> 0.2206984 | F45: =F39*F43 -> 0.10606576 | G45: =G39*G43 -> 0.45277507 | H45: =H39*H43 -> 0.65304074
B47: DuPont Analysis Summary
B48: (FY2021–FY2025 for NVIDIA)
B50: ROE increased significantly from ~26% in FY2021 to ~92% in FY2025, indicating a substantial improvement in shareholder returns over the period.
B51: Net Profit Margin rose sharply, especially after FY2023, driven by strong demand for AI and data-center GPUs and improved pricing power.
B52: Asset Turnover improved steadily, meaning NVIDIA generated more revenue per dollar of assets as operations scaled.
B53: Equity Multiplier declined slightly, indicating the company relied less on financial leverage over time.
B54: The rise in ROE was primarily driven by operational performance (profitability and efficiency) rather than increased debt.
B55: ROA also increased substantially, reflecting improved asset productivity and stronger overall operational efficiency.
B56: Overall, the DuPont analysis shows that NVIDIA’s growth in shareholder returns was mainly supported by higher margins and better asset utilization, not financial leverage.

Sheet ALTMAN SCORE
B6: Altman Z-Score Calculation:
B7: Working Capital / Total Assets
D8: FY2021 | E8: FY2022 | F8: FY2023 | G8: FY2024 | H8: FY2025
B9: Working Capital | D9: 12561 | E9: 24494 | F9: 16510 | G9: 33714 | H9: 62079
B10: Total Assets | D10: 28791 | E10: 44187 | F10: 41182 | G10: 65728 | H10: 111601
B11: Working Capital / Total Assets (A) | D11: 0.44 | E11: 0.55 | F11: 0.4 | G11: 0.51 | H11: 0.56
B13: Retained Earnings / Total Assets
D14: FY2021 | E14: FY2022 | F14: FY2023 | G14: FY2024 | H14: FY2025
B15: Retained Earnings | D15: 18908 | E15: 16235 | F15: 10171 | G15: 29817 | H15: 68038
B16: Total Assets | D16: 28791 | E16: 44187 | F16: 41182 | G16: 65728 | H16: 111601
B17: Retained Earnings / Total Assets (B) | D17: 0.66 | E17: 0.37 | F17: 0.25 | G17: 0.45 | H17: 0.61
B19: EBIT / Total Assets
D20: FY2021 | E20: FY2022 | F20: FY2023 | G20: FY2024 | H20: FY2025
B21: EBIT | D21: 4532 | E21: 10041 | F21: 5577 | G21: 32972 | H21: 81453
B22: Total Assets | D22: 28791 | E22: 44187 | F22: 41182 | G22: 65728 | H22: 111601
B23: EBIT / Total Assets (C) | D23: 0.16 | E23: 0.23 | F23: 0.14 | G23: 0.5 | H23: 0.73
B25: Market Capitalisation / Total Liabilities
D26: FY2021 | E26: FY2022 | F26: FY2023 | G26: FY2024 | H26: FY2025
B27: Market Capitalisation | D27: 350000 | E27: 450000 | F27: 600000 | G27: 1200000 | H27: 2728440
B28: Total Liabilities | D28: 11898 | E28: 17575 | F28: 19081 | G28: 22750 | H28: 32274
B29: Market Cap / Total Liabilities (D) | D29: 29.41 | E29: 25.61 | F29: 31.45 | G29: 52.75 | H29: 84.52
B31: Sales / Total Assets
D32: FY2021 | E32: FY2022 | F32: FY2023 | G32: FY2024 | H32: FY2025
B33: Sales | D33: 16675 | E33: 26914 | F33: 26974 | G33: 60922 | H33: 130497
B34: Total Assets | D34: 28791 | E34: 44187 | F34: 41182 | G34: 65728 | H34: 111601
B35: Sales / Total Assets (E) | D35: 0.58 | E35: 0.61 | F35: 0.65 | G35: 0.93 | H35: 1.17
B37: Altman Z-Score
D38: FY2021 | E38: FY2022 | F38: FY2023 | G38: FY2024 | H38: FY2025
B39: Altman Z-Score | D39: 20.8 | E39: 19.3 | F39: 22.4 | G39: 36.7 | H39: 58.9
B40: Status | D40: Safe | E40: Safe | F40: Safe | G40: Safe | H40: Safe
B42: Score | D42: Interpretation
B43: 2.99 | Safe zone | | D43: NVIDIA’s scores are far above 2.99, indicating extremely low bankruptcy risk and strong financial stability.
B44: 1.81 – 2.99 | Grey zone |
B45: < 1.81 | Distress zone |

Sheet Sheet1
B2: NVIDIA DCF
B8: Assumptions
B10: Switches | G10: Conservative | L10: Base | Q10: Optimistic
B11: Assumptions | D11: Year | E11: Metric | G11: Assumptions | I11: Year | J11: Metric | L11: Assumptions | N11: Year | O11: Metric | Q11: Assumptions | S11: Year | T11: Metric
B12: Revenue | G12: Revenue | Q12: Revenue
B13: EBIT | G13: Revenue | L13: Revenue | Q13: Revenue
B14: WACC | G14: EBIT | Q14: EBIT
B15: TGR | G15: EBIT | L15: EBIT | Q15: EBIT
B17: Valuation | G17: Valuation | L17: Valuation | Q17: Valuation
B18: WACC | G18: WACC | L18: WACC | Q18: WACC
B19: TGR | G19: TGR | L19: TGR | Q19: TGR
B21: Income Statement | E21: 2025E | F21: 2024E | G21: 2023E | H21: 2021E | I21: 2022E | J21: 2020E | K21: 2019E | L21: 2018E | M21: 2017E | N21: 2016E | O21: 2026A | P21: 2027A | Q21: 2028A | R21: 2029A
B22: Revenue | E22: 5010 | F22: 6910 | G22: 9714 | H22: 10918 | I22: 11716 | J22: 16675 | K22: 26914 | L22: 26974 | M22: 60922 | N22: 130497
B23: % growth
B25: EBIT
B26: % of sales
B31: Cash Flow | E31: 2016E | F31: 2017E | G31: 2018E | H31: 2019E | I31: 2020E | J31: 2021E | K31: 2022E | L31: 2023E | M31: 2024E | N31: 2025E | O31: 2026A | P31: 2027A | Q31: 2028A | R31: 2029A
B32: D&A
B33: % of sales
B35: CapEx
B36: % of sales
B38: Change IN NWC
B39: % of sales
B40: % of change in sales
B42: DCF | E42: 2016E | F42: 2017E | G42: 2018E | H42: 2019E | I42: 2020E | J42: 2021E | K42: 2022E | L42: 2023E | M42: 2024E | N42: 2025E | O42: 2026A | P42: 2027A | Q42: 2028A | R42: 2029A
B43: Revenue
B44: % growth
B49: EBIT
B50: % of sales
B55: Taxes
B56: Taxes Rate

Sheet Sheet2
